----------------------------------------------------------------------
Traceback (most recent call last):
  File ".\my_test.py", line 9, in test_sum
    self.assertEqual(calculation.get_sum(), 11, 'The sum is wrong.')
AssertionError: 10 != 11 : The sum is wrong.
----------------------------------------------------------------------
Ran 1 test in 0.001s